[2022-10-27 02:16:26,197] {taskinstance.py:1159} INFO - Dependencies all met for <TaskInstance: user_processing.process_user scheduled__2022-10-26T00:00:00+00:00 [queued]>
[2022-10-27 02:16:26,233] {taskinstance.py:1159} INFO - Dependencies all met for <TaskInstance: user_processing.process_user scheduled__2022-10-26T00:00:00+00:00 [queued]>
[2022-10-27 02:16:26,258] {taskinstance.py:1356} INFO - 
--------------------------------------------------------------------------------
[2022-10-27 02:16:26,260] {taskinstance.py:1357} INFO - Starting attempt 1 of 1
[2022-10-27 02:16:26,263] {taskinstance.py:1358} INFO - 
--------------------------------------------------------------------------------
[2022-10-27 02:16:26,283] {taskinstance.py:1377} INFO - Executing <Task(PythonOperator): process_user> on 2022-10-26 00:00:00+00:00
[2022-10-27 02:16:26,302] {standard_task_runner.py:52} INFO - Started process 148 to run task
[2022-10-27 02:16:26,310] {standard_task_runner.py:79} INFO - Running: ['***', 'tasks', 'run', 'user_processing', 'process_user', 'scheduled__2022-10-26T00:00:00+00:00', '--job-id', '7', '--raw', '--subdir', 'DAGS_FOLDER/user_processing.py', '--cfg-path', '/tmp/tmpb0dikqcw', '--error-file', '/tmp/tmpblv_slau']
[2022-10-27 02:16:26,316] {standard_task_runner.py:80} INFO - Job 7: Subtask process_user
[2022-10-27 02:16:26,448] {task_command.py:369} INFO - Running <TaskInstance: user_processing.process_user scheduled__2022-10-26T00:00:00+00:00 [running]> on host 18112c9f481e
[2022-10-27 02:16:26,578] {taskinstance.py:1571} INFO - Exporting the following env vars:
AIRFLOW_CTX_DAG_OWNER=***
AIRFLOW_CTX_DAG_ID=user_processing
AIRFLOW_CTX_TASK_ID=process_user
AIRFLOW_CTX_EXECUTION_DATE=2022-10-26T00:00:00+00:00
AIRFLOW_CTX_TRY_NUMBER=1
AIRFLOW_CTX_DAG_RUN_ID=scheduled__2022-10-26T00:00:00+00:00
[2022-10-27 02:16:26,585] {taskinstance.py:1889} ERROR - Task failed with exception
Traceback (most recent call last):
  File "/home/airflow/.local/lib/python3.7/site-packages/airflow/operators/python.py", line 171, in execute
    return_value = self.execute_callable()
  File "/home/airflow/.local/lib/python3.7/site-packages/airflow/operators/python.py", line 189, in execute_callable
    return self.python_callable(*self.op_args, **self.op_kwargs)
  File "/opt/airflow/dags/user_processing.py", line 12, in process_user
    user=ti.xcomm_pull(task_ids = 'extract_user')
AttributeError: 'TaskInstance' object has no attribute 'xcomm_pull'
[2022-10-27 02:16:26,605] {taskinstance.py:1400} INFO - Marking task as FAILED. dag_id=user_processing, task_id=process_user, execution_date=20221026T000000, start_date=20221027T021626, end_date=20221027T021626
[2022-10-27 02:16:26,625] {standard_task_runner.py:97} ERROR - Failed to execute job 7 for task process_user ('TaskInstance' object has no attribute 'xcomm_pull'; 148)
[2022-10-27 02:16:26,697] {local_task_job.py:156} INFO - Task exited with return code 1
[2022-10-27 02:16:26,806] {local_task_job.py:273} INFO - 0 downstream tasks scheduled from follow-on schedule check
