[2022-10-27 13:50:49,978] {taskinstance.py:1159} INFO - Dependencies all met for <TaskInstance: user_processing.store_user manual__2022-10-27T13:50:39.586377+00:00 [queued]>
[2022-10-27 13:50:49,989] {taskinstance.py:1159} INFO - Dependencies all met for <TaskInstance: user_processing.store_user manual__2022-10-27T13:50:39.586377+00:00 [queued]>
[2022-10-27 13:50:49,991] {taskinstance.py:1356} INFO - 
--------------------------------------------------------------------------------
[2022-10-27 13:50:49,992] {taskinstance.py:1357} INFO - Starting attempt 1 of 1
[2022-10-27 13:50:49,993] {taskinstance.py:1358} INFO - 
--------------------------------------------------------------------------------
[2022-10-27 13:50:50,005] {taskinstance.py:1377} INFO - Executing <Task(PythonOperator): store_user> on 2022-10-27 13:50:39.586377+00:00
[2022-10-27 13:50:50,013] {standard_task_runner.py:52} INFO - Started process 28002 to run task
[2022-10-27 13:50:50,021] {standard_task_runner.py:79} INFO - Running: ['***', 'tasks', 'run', 'user_processing', 'store_user', 'manual__2022-10-27T13:50:39.586377+00:00', '--job-id', '28', '--raw', '--subdir', 'DAGS_FOLDER/user_processing.py', '--cfg-path', '/tmp/tmpwgchqamw', '--error-file', '/tmp/tmp3bwfc32z']
[2022-10-27 13:50:50,024] {standard_task_runner.py:80} INFO - Job 28: Subtask store_user
[2022-10-27 13:50:50,097] {task_command.py:369} INFO - Running <TaskInstance: user_processing.store_user manual__2022-10-27T13:50:39.586377+00:00 [running]> on host 18112c9f481e
[2022-10-27 13:50:50,156] {taskinstance.py:1571} INFO - Exporting the following env vars:
AIRFLOW_CTX_DAG_OWNER=***
AIRFLOW_CTX_DAG_ID=user_processing
AIRFLOW_CTX_TASK_ID=store_user
AIRFLOW_CTX_EXECUTION_DATE=2022-10-27T13:50:39.586377+00:00
AIRFLOW_CTX_TRY_NUMBER=1
AIRFLOW_CTX_DAG_RUN_ID=manual__2022-10-27T13:50:39.586377+00:00
[2022-10-27 13:50:50,159] {taskinstance.py:1889} ERROR - Task failed with exception
Traceback (most recent call last):
  File "/home/airflow/.local/lib/python3.7/site-packages/airflow/operators/python.py", line 171, in execute
    return_value = self.execute_callable()
  File "/home/airflow/.local/lib/python3.7/site-packages/airflow/operators/python.py", line 189, in execute_callable
    return self.python_callable(*self.op_args, **self.op_kwargs)
  File "/opt/airflow/dags/user_processing.py", line 28, in store_user
    hook.copy_expert(
AttributeError: 'tuple' object has no attribute 'copy_expert'
[2022-10-27 13:50:50,174] {taskinstance.py:1400} INFO - Marking task as FAILED. dag_id=user_processing, task_id=store_user, execution_date=20221027T135039, start_date=20221027T135049, end_date=20221027T135050
[2022-10-27 13:50:50,182] {standard_task_runner.py:97} ERROR - Failed to execute job 28 for task store_user ('tuple' object has no attribute 'copy_expert'; 28002)
[2022-10-27 13:50:50,194] {local_task_job.py:156} INFO - Task exited with return code 1
[2022-10-27 13:50:50,223] {local_task_job.py:273} INFO - 0 downstream tasks scheduled from follow-on schedule check
