[2022-10-27 02:20:19,689] {taskinstance.py:1159} INFO - Dependencies all met for <TaskInstance: user_processing.store_user manual__2022-10-27T02:20:17.398602+00:00 [queued]>
[2022-10-27 02:20:19,719] {taskinstance.py:1159} INFO - Dependencies all met for <TaskInstance: user_processing.store_user manual__2022-10-27T02:20:17.398602+00:00 [queued]>
[2022-10-27 02:20:19,722] {taskinstance.py:1356} INFO - 
--------------------------------------------------------------------------------
[2022-10-27 02:20:19,725] {taskinstance.py:1357} INFO - Starting attempt 1 of 1
[2022-10-27 02:20:19,726] {taskinstance.py:1358} INFO - 
--------------------------------------------------------------------------------
[2022-10-27 02:20:19,765] {taskinstance.py:1377} INFO - Executing <Task(PythonOperator): store_user> on 2022-10-27 02:20:17.398602+00:00
[2022-10-27 02:20:19,794] {standard_task_runner.py:52} INFO - Started process 347 to run task
[2022-10-27 02:20:19,824] {standard_task_runner.py:79} INFO - Running: ['***', 'tasks', 'run', 'user_processing', 'store_user', 'manual__2022-10-27T02:20:17.398602+00:00', '--job-id', '12', '--raw', '--subdir', 'DAGS_FOLDER/user_processing.py', '--cfg-path', '/tmp/tmpxpd3oemh', '--error-file', '/tmp/tmpqtj45n0t']
[2022-10-27 02:20:19,831] {standard_task_runner.py:80} INFO - Job 12: Subtask store_user
[2022-10-27 02:20:20,082] {task_command.py:369} INFO - Running <TaskInstance: user_processing.store_user manual__2022-10-27T02:20:17.398602+00:00 [running]> on host 18112c9f481e
[2022-10-27 02:20:20,350] {taskinstance.py:1571} INFO - Exporting the following env vars:
AIRFLOW_CTX_DAG_OWNER=***
AIRFLOW_CTX_DAG_ID=user_processing
AIRFLOW_CTX_TASK_ID=store_user
AIRFLOW_CTX_EXECUTION_DATE=2022-10-27T02:20:17.398602+00:00
AIRFLOW_CTX_TRY_NUMBER=1
AIRFLOW_CTX_DAG_RUN_ID=manual__2022-10-27T02:20:17.398602+00:00
[2022-10-27 02:20:20,365] {taskinstance.py:1889} ERROR - Task failed with exception
Traceback (most recent call last):
  File "/home/airflow/.local/lib/python3.7/site-packages/airflow/operators/python.py", line 171, in execute
    return_value = self.execute_callable()
  File "/home/airflow/.local/lib/python3.7/site-packages/airflow/operators/python.py", line 189, in execute_callable
    return self.python_callable(*self.op_args, **self.op_kwargs)
  File "/opt/airflow/dags/user_processing.py", line 28, in store_user
    hook.copy_expert(
AttributeError: 'tuple' object has no attribute 'copy_expert'
[2022-10-27 02:20:20,388] {taskinstance.py:1400} INFO - Marking task as FAILED. dag_id=user_processing, task_id=store_user, execution_date=20221027T022017, start_date=20221027T022019, end_date=20221027T022020
[2022-10-27 02:20:20,425] {standard_task_runner.py:97} ERROR - Failed to execute job 12 for task store_user ('tuple' object has no attribute 'copy_expert'; 347)
[2022-10-27 02:20:20,495] {local_task_job.py:156} INFO - Task exited with return code 1
[2022-10-27 02:20:20,563] {local_task_job.py:273} INFO - 0 downstream tasks scheduled from follow-on schedule check
