[2022-10-27 02:20:20,732] {taskinstance.py:1159} INFO - Dependencies all met for <TaskInstance: user_processing.process_user manual__2022-10-27T02:20:17.398602+00:00 [queued]>
[2022-10-27 02:20:20,742] {taskinstance.py:1159} INFO - Dependencies all met for <TaskInstance: user_processing.process_user manual__2022-10-27T02:20:17.398602+00:00 [queued]>
[2022-10-27 02:20:20,743] {taskinstance.py:1356} INFO - 
--------------------------------------------------------------------------------
[2022-10-27 02:20:20,744] {taskinstance.py:1357} INFO - Starting attempt 1 of 1
[2022-10-27 02:20:20,744] {taskinstance.py:1358} INFO - 
--------------------------------------------------------------------------------
[2022-10-27 02:20:20,759] {taskinstance.py:1377} INFO - Executing <Task(PythonOperator): process_user> on 2022-10-27 02:20:17.398602+00:00
[2022-10-27 02:20:20,767] {standard_task_runner.py:52} INFO - Started process 350 to run task
[2022-10-27 02:20:20,772] {standard_task_runner.py:79} INFO - Running: ['***', 'tasks', 'run', 'user_processing', 'process_user', 'manual__2022-10-27T02:20:17.398602+00:00', '--job-id', '15', '--raw', '--subdir', 'DAGS_FOLDER/user_processing.py', '--cfg-path', '/tmp/tmpk2jorpfz', '--error-file', '/tmp/tmp_pnj2qnj']
[2022-10-27 02:20:20,774] {standard_task_runner.py:80} INFO - Job 15: Subtask process_user
[2022-10-27 02:20:20,850] {task_command.py:369} INFO - Running <TaskInstance: user_processing.process_user manual__2022-10-27T02:20:17.398602+00:00 [running]> on host 18112c9f481e
[2022-10-27 02:20:20,911] {taskinstance.py:1571} INFO - Exporting the following env vars:
AIRFLOW_CTX_DAG_OWNER=***
AIRFLOW_CTX_DAG_ID=user_processing
AIRFLOW_CTX_TASK_ID=process_user
AIRFLOW_CTX_EXECUTION_DATE=2022-10-27T02:20:17.398602+00:00
AIRFLOW_CTX_TRY_NUMBER=1
AIRFLOW_CTX_DAG_RUN_ID=manual__2022-10-27T02:20:17.398602+00:00
[2022-10-27 02:20:20,923] {taskinstance.py:1889} ERROR - Task failed with exception
Traceback (most recent call last):
  File "/home/airflow/.local/lib/python3.7/site-packages/airflow/operators/python.py", line 171, in execute
    return_value = self.execute_callable()
  File "/home/airflow/.local/lib/python3.7/site-packages/airflow/operators/python.py", line 189, in execute_callable
    return self.python_callable(*self.op_args, **self.op_kwargs)
  File "/opt/airflow/dags/user_processing.py", line 15, in process_user
    user = user['results'][0]
TypeError: 'NoneType' object is not subscriptable
[2022-10-27 02:20:20,932] {taskinstance.py:1400} INFO - Marking task as FAILED. dag_id=user_processing, task_id=process_user, execution_date=20221027T022017, start_date=20221027T022020, end_date=20221027T022020
[2022-10-27 02:20:20,938] {standard_task_runner.py:97} ERROR - Failed to execute job 15 for task process_user ('NoneType' object is not subscriptable; 350)
[2022-10-27 02:20:20,949] {local_task_job.py:156} INFO - Task exited with return code 1
[2022-10-27 02:20:20,976] {local_task_job.py:273} INFO - 0 downstream tasks scheduled from follow-on schedule check
