[2022-10-27 02:28:36,378] {taskinstance.py:1159} INFO - Dependencies all met for <TaskInstance: user_processing.process_user manual__2022-10-27T02:28:29.323113+00:00 [queued]>
[2022-10-27 02:28:36,385] {taskinstance.py:1159} INFO - Dependencies all met for <TaskInstance: user_processing.process_user manual__2022-10-27T02:28:29.323113+00:00 [queued]>
[2022-10-27 02:28:36,385] {taskinstance.py:1356} INFO - 
--------------------------------------------------------------------------------
[2022-10-27 02:28:36,386] {taskinstance.py:1357} INFO - Starting attempt 1 of 1
[2022-10-27 02:28:36,387] {taskinstance.py:1358} INFO - 
--------------------------------------------------------------------------------
[2022-10-27 02:28:36,394] {taskinstance.py:1377} INFO - Executing <Task(PythonOperator): process_user> on 2022-10-27 02:28:29.323113+00:00
[2022-10-27 02:28:36,399] {standard_task_runner.py:52} INFO - Started process 760 to run task
[2022-10-27 02:28:36,403] {standard_task_runner.py:79} INFO - Running: ['***', 'tasks', 'run', 'user_processing', 'process_user', 'manual__2022-10-27T02:28:29.323113+00:00', '--job-id', '19', '--raw', '--subdir', 'DAGS_FOLDER/user_processing.py', '--cfg-path', '/tmp/tmpiwf5xnm1', '--error-file', '/tmp/tmp20bdzdzf']
[2022-10-27 02:28:36,404] {standard_task_runner.py:80} INFO - Job 19: Subtask process_user
[2022-10-27 02:28:36,495] {task_command.py:369} INFO - Running <TaskInstance: user_processing.process_user manual__2022-10-27T02:28:29.323113+00:00 [running]> on host 18112c9f481e
[2022-10-27 02:28:36,544] {taskinstance.py:1571} INFO - Exporting the following env vars:
AIRFLOW_CTX_DAG_OWNER=***
AIRFLOW_CTX_DAG_ID=user_processing
AIRFLOW_CTX_TASK_ID=process_user
AIRFLOW_CTX_EXECUTION_DATE=2022-10-27T02:28:29.323113+00:00
AIRFLOW_CTX_TRY_NUMBER=1
AIRFLOW_CTX_DAG_RUN_ID=manual__2022-10-27T02:28:29.323113+00:00
[2022-10-27 02:28:36,570] {taskinstance.py:1889} ERROR - Task failed with exception
Traceback (most recent call last):
  File "/home/airflow/.local/lib/python3.7/site-packages/airflow/operators/python.py", line 171, in execute
    return_value = self.execute_callable()
  File "/home/airflow/.local/lib/python3.7/site-packages/airflow/operators/python.py", line 189, in execute_callable
    return self.python_callable(*self.op_args, **self.op_kwargs)
  File "/opt/airflow/dags/user_processing.py", line 24, in process_user
    processed_user.to_csv('tmp/processed_user.csv', header=False, index = None )
  File "/home/airflow/.local/lib/python3.7/site-packages/pandas/core/generic.py", line 3482, in to_csv
    storage_options=storage_options,
  File "/home/airflow/.local/lib/python3.7/site-packages/pandas/io/formats/format.py", line 1105, in to_csv
    csv_formatter.save()
  File "/home/airflow/.local/lib/python3.7/site-packages/pandas/io/formats/csvs.py", line 243, in save
    storage_options=self.storage_options,
  File "/home/airflow/.local/lib/python3.7/site-packages/pandas/io/common.py", line 707, in get_handle
    newline="",
FileNotFoundError: [Errno 2] No such file or directory: 'tmp/processed_user.csv'
[2022-10-27 02:28:36,586] {taskinstance.py:1400} INFO - Marking task as FAILED. dag_id=user_processing, task_id=process_user, execution_date=20221027T022829, start_date=20221027T022836, end_date=20221027T022836
[2022-10-27 02:28:36,592] {standard_task_runner.py:97} ERROR - Failed to execute job 19 for task process_user ([Errno 2] No such file or directory: 'tmp/processed_user.csv'; 760)
[2022-10-27 02:28:36,619] {local_task_job.py:156} INFO - Task exited with return code 1
[2022-10-27 02:28:36,647] {local_task_job.py:273} INFO - 0 downstream tasks scheduled from follow-on schedule check
